--- sage/doctest/control.py.orig	2013-11-29 09:17:15.000000000 +1300
+++ sage/doctest/control.py	2013-12-11 15:43:17.181660078 +1300
@@ -372,40 +372,6 @@
         sys.stdout.write(s)
         sys.stdout.flush()
 
-    def test_safe_directory(self, dir=None):
-        """
-        Test that the given directory is safe to run Python code from.
-
-        We use the check added to Python for this, which gives a
-        warning when the current directory is considered unsafe.  We promote
-        this warning to an error with ``-Werror``.  See
-        ``sage/tests/cmdline.py`` for a doctest that this works, see
-        also :trac:`13579`.
-
-        TESTS::
-
-            sage: from sage.doctest.control import DocTestDefaults, DocTestController
-            sage: DD = DocTestDefaults()
-            sage: DC = DocTestController(DD, [])
-            sage: DC.test_safe_directory()
-            sage: d = os.path.join(tmp_dir(), "test")
-            sage: os.mkdir(d)
-            sage: os.chmod(d, 0o777)
-            sage: DC.test_safe_directory(d)
-            Traceback (most recent call last):
-            ...
-            RuntimeError: refusing to run doctests...
-        """
-        import subprocess
-        with open(os.devnull, 'w') as dev_null:
-            if subprocess.call(['python', '-Werror', '-c', ''],
-                    stdout=dev_null, stderr=dev_null, cwd=dir) != 0:
-                raise RuntimeError(
-                      "refusing to run doctests from the current "
-                      "directory '{}' since untrusted users could put files in "
-                      "this directory, making it unsafe to run Sage code from"
-                      .format(os.getcwd()))
-
     def create_run_id(self):
         """
         Creates the run id.
@@ -894,7 +860,6 @@
                 return 2
             return self.run_val_gdb()
         else:
-            self.test_safe_directory()
             self.create_run_id()
             self.add_files()
             self.expand_files_into_sources()
--- sage/tests/cmdline.py.orig	2013-12-11 15:44:10.972734490 +1300
+++ sage/tests/cmdline.py	2013-12-11 15:45:29.909843806 +1300
@@ -348,24 +348,6 @@
         sage: ret
         1
 
-    Check that Sage refuses to run doctests from a directory whose
-    permissions are too loose.  We create a world-writable directory
-    inside a safe temporary directory to test this::
-
-        sage: d = os.path.join(tmp_dir(), "test")
-        sage: os.mkdir(d)
-        sage: os.chmod(d, 0o777)
-        sage: (out, err, ret) = test_executable(["sage", "-t", "nonexisting.py"], cwd=d)
-        sage: print err
-        Traceback (most recent call last):
-        ...
-        RuntimeError: refusing to run doctests...
-        sage: (out, err, ret) = test_executable(["sage", "-tp", "1", "nonexisting.py"], cwd=d)
-        sage: print err
-        Traceback (most recent call last):
-        ...
-        RuntimeError: refusing to run doctests...
-
     Now run a test for the fixdoctests script and, in particular, check that the
     issues raised in :trac:`10589` are fixed. We have to go to slightly silly
     lengths to doctest the output.::
